<?xml version="1.0" encoding="UTF-8"?>
<testng-results ignored="0" total="1" passed="0" failed="0" skipped="1">
  <reporter-output>
  </reporter-output>
  <suite started-at="2018-07-16T09:57:21Z" name="Default suite" finished-at="2018-07-16T09:57:21Z" duration-ms="58">
    <groups>
    </groups>
    <test started-at="2018-07-16T09:57:21Z" name="Default test" finished-at="2018-07-16T09:57:21Z" duration-ms="58">
      <class name="testcases.login">
        <test-method signature="loginapplication(java.lang.String, java.lang.String, java.lang.String)[pri:0, instance:testcases.login@71238fc2]" started-at="2018-07-16T15:27:21Z" name="loginapplication" data-provider="login1" finished-at="2018-07-16T15:27:21Z" duration-ms="0" status="SKIP">
          <exception class="java.lang.RuntimeException">
            <message>
              <![CDATA[java.lang.ArrayIndexOutOfBoundsException: 2]]>
            </message>
            <full-stacktrace>
              <![CDATA[java.lang.RuntimeException: java.lang.ArrayIndexOutOfBoundsException: 2at org.testng.internal.MethodInvocationHelper.invokeMethodNoCheckedException(MethodInvocationHelper.java:49)at org.testng.internal.MethodInvocationHelper.invokeDataProvider(MethodInvocationHelper.java:131)at org.testng.internal.Parameters.handleParameters(Parameters.java:706)at org.testng.internal.ParameterHandler.handleParameters(ParameterHandler.java:49)at org.testng.internal.ParameterHandler.createParameters(ParameterHandler.java:37)at org.testng.internal.Invoker.invokeTestMethods(Invoker.java:914)at org.testng.internal.TestMethodWorker.invokeTestMethods(TestMethodWorker.java:125)at org.testng.internal.TestMethodWorker.run(TestMethodWorker.java:109)at org.testng.TestRunner.privateRun(TestRunner.java:648)at org.testng.TestRunner.run(TestRunner.java:505)at org.testng.SuiteRunner.runTest(SuiteRunner.java:455)at org.testng.SuiteRunner.runSequentially(SuiteRunner.java:450)at org.testng.SuiteRunner.privateRun(SuiteRunner.java:415)at org.testng.SuiteRunner.run(SuiteRunner.java:364)at org.testng.SuiteRunnerWorker.runSuite(SuiteRunnerWorker.java:52)at org.testng.SuiteRunnerWorker.run(SuiteRunnerWorker.java:84)at org.testng.TestNG.runSuitesSequentially(TestNG.java:1187)at org.testng.TestNG.runSuitesLocally(TestNG.java:1116)at org.testng.TestNG.runSuites(TestNG.java:1028)at org.testng.TestNG.run(TestNG.java:996)at org.testng.remote.AbstractRemoteTestNG.run(AbstractRemoteTestNG.java:114)at org.testng.remote.RemoteTestNG.initAndRun(RemoteTestNG.java:251)at org.testng.remote.RemoteTestNG.main(RemoteTestNG.java:77)Caused by: java.lang.ArrayIndexOutOfBoundsException: 2at testcases.login.login1(login.java:30)at java.base/jdk.internal.reflect.NativeMethodAccessorImpl.invoke0(Native Method)at java.base/jdk.internal.reflect.NativeMethodAccessorImpl.invoke(NativeMethodAccessorImpl.java:62)at java.base/jdk.internal.reflect.DelegatingMethodAccessorImpl.invoke(DelegatingMethodAccessorImpl.java:43)at java.base/java.lang.reflect.Method.invoke(Method.java:564)at org.testng.internal.MethodInvocationHelper.invokeMethod(MethodInvocationHelper.java:124)at org.testng.internal.MethodInvocationHelper.invokeMethod(MethodInvocationHelper.java:74)at org.testng.internal.MethodInvocationHelper.invokeMethodNoCheckedException(MethodInvocationHelper.java:45)... 22 more]]>
            </full-stacktrace>
          </exception> <!-- java.lang.RuntimeException -->
          <reporter-output>
          </reporter-output>
        </test-method> <!-- loginapplication -->
      </class> <!-- testcases.login -->
    </test> <!-- Default test -->
  </suite> <!-- Default suite -->
</testng-results>
